<?xml version="1.0" ?>

<robot name="basic_amr">
  
  <material name="white">
    <color rgba="1 1 1 1"/>
  </material>

  <material name="black">
    <color rgba="0 0 0 1"/>
  </material>

  <material name="green">
    <color rgba="0.1 0.8 0.1 1"/>
  </material>

  <!-- Begin - Robot description -->

  <link name="base_link" />

  <joint name="base__base_link" type="fixed">
    <parent link="base_link"/>
    <child link="base"/>
  </joint>

  <link name="base">
    <origin rpy="0 0 0" xyz="0.00 0 0.00"/>
    <visual>
      <geometry>
        <box size="0.08 0.05 0.002"/>
      </geometry>
      <material name="green"/>
    </visual>
  </link>

  <link name="fcastor_wheel">
    <origin rpy="0 0 0" xyz="0.00 0 0.00"/>
    <visual>
      <geometry>
        <cylinder length="0.006" radius="0.0035"/>
      </geometry>
      <material name="black"/>
    </visual>
  </link>
  
  <joint name="base__fcastor_wheel" type="continuous">
    <parent link="base"/>
    <child link="fcastor_wheel"/>
    <origin xyz="0.028 0 -0.005" rpy="1.5708 0 0"/>
    <axis xyz="0 0 1"/>
  </joint>

  <link name="bcastor_wheel">
    <origin rpy="0 0 0" xyz="0.00 0 0.00"/>
    <visual>
      <geometry>
        <cylinder length="0.006" radius="0.0035"/>
      </geometry>
      <material name="black"/>
    </visual>
  </link>
  
  <joint name="base__bcastor_wheel" type="continuous">
    <parent link="base"/>
    <child link="bcastor_wheel"/>
    <origin xyz="-0.028 0 -0.005" rpy="1.5708 0 0"/>
    <axis xyz="0 0 1"/>
  </joint>

  <!-- End - Robot description -->

</robot>